{
 "cells": [
  {
   "cell_type": "code",
   "execution_count": 1,
   "id": "6e5d74d3",
   "metadata": {},
   "outputs": [],
   "source": [
    "import os\n",
    "import json\n",
    "\n",
    "import boto3\n",
    "import sagemaker\n",
    "from sagemaker.pytorch import PyTorchModel\n",
    "from sagemaker import get_execution_role, Session\n",
    "\n",
    "\n",
    "\n",
    "sess = Session()\n",
    "\n",
    "role = get_execution_role()\n",
    "model_dir = \"/home/ec2-user/SageMaker/smoke-detection-smokeynet/src\" # Replace with S3"
   ]
  },
  {
   "cell_type": "code",
   "execution_count": 2,
   "id": "d046974c",
   "metadata": {},
   "outputs": [],
   "source": [
    "pt_mnist_model_data = sess.upload_data(\n",
    "    path=\"/home/ec2-user/SageMaker/smoke-detection-smokeynet/src/last.tar.gz\", bucket=sess.default_bucket(), key_prefix=\"model/pytorch\"\n",
    ")"
   ]
  },
  {
   "cell_type": "code",
   "execution_count": 3,
   "id": "583fd3a0",
   "metadata": {},
   "outputs": [],
   "source": [
    "model = PyTorchModel(\n",
    "    entry_point=\"inference.py\",\n",
    "    source_dir=model_dir,\n",
    "    role=role,\n",
    "    model_data=pt_mnist_model_data,\n",
    "    framework_version=\"1.5.0\",\n",
    "    py_version=\"py3\",\n",
    ")"
   ]
  },
  {
   "cell_type": "code",
   "execution_count": null,
   "id": "8eebb7b7",
   "metadata": {},
   "outputs": [],
   "source": []
  },
  {
   "cell_type": "markdown",
   "id": "621ad691",
   "metadata": {},
   "source": [
    "#### Deploy Model"
   ]
  },
  {
   "cell_type": "code",
   "execution_count": 4,
   "id": "76823826",
   "metadata": {},
   "outputs": [
    {
     "name": "stdout",
     "output_type": "stream",
     "text": [
      "---------!"
     ]
    }
   ],
   "source": [
    "from sagemaker.serializers import JSONSerializer\n",
    "from sagemaker.deserializers import JSONDeserializer\n",
    "\n",
    "\n",
    "local_mode = False\n",
    "\n",
    "if local_mode:\n",
    "    instance_type = \"local\"\n",
    "else:\n",
    "    instance_type = \"ml.g4dn.xlarge\"\n",
    "\n",
    "predictor = model.deploy(\n",
    "    initial_instance_count=1,\n",
    "    instance_type=instance_type,\n",
    "    serializer=JSONSerializer(),\n",
    "    deserializer=JSONDeserializer(),\n",
    ")"
   ]
  },
  {
   "cell_type": "code",
   "execution_count": 5,
   "id": "7ef73c44",
   "metadata": {},
   "outputs": [
    {
     "ename": "NameError",
     "evalue": "name 's3_client' is not defined",
     "output_type": "error",
     "traceback": [
      "\u001b[0;31m---------------------------------------------------------------------------\u001b[0m",
      "\u001b[0;31mNameError\u001b[0m                                 Traceback (most recent call last)",
      "\u001b[0;32m/tmp/ipykernel_20523/548138325.py\u001b[0m in \u001b[0;36m<cell line: 12>\u001b[0;34m()\u001b[0m\n\u001b[1;32m     10\u001b[0m \u001b[0mpickle\u001b[0m\u001b[0;34m.\u001b[0m\u001b[0mdump\u001b[0m\u001b[0;34m(\u001b[0m\u001b[0mdummy_data\u001b[0m\u001b[0;34m,\u001b[0m \u001b[0mmy_array_data\u001b[0m\u001b[0;34m)\u001b[0m\u001b[0;34m\u001b[0m\u001b[0;34m\u001b[0m\u001b[0m\n\u001b[1;32m     11\u001b[0m \u001b[0mmy_array_data\u001b[0m\u001b[0;34m.\u001b[0m\u001b[0mseek\u001b[0m\u001b[0;34m(\u001b[0m\u001b[0;36m0\u001b[0m\u001b[0;34m)\u001b[0m\u001b[0;34m\u001b[0m\u001b[0;34m\u001b[0m\u001b[0m\n\u001b[0;32m---> 12\u001b[0;31m \u001b[0ms3_client\u001b[0m\u001b[0;34m.\u001b[0m\u001b[0mupload_fileobj\u001b[0m\u001b[0;34m(\u001b[0m\u001b[0mmy_array_data\u001b[0m\u001b[0;34m,\u001b[0m \u001b[0mbucket\u001b[0m\u001b[0;34m,\u001b[0m \u001b[0;34m'mydummydata.pkl'\u001b[0m\u001b[0;34m)\u001b[0m\u001b[0;34m\u001b[0m\u001b[0;34m\u001b[0m\u001b[0m\n\u001b[0m",
      "\u001b[0;31mNameError\u001b[0m: name 's3_client' is not defined"
     ]
    }
   ],
   "source": [
    "import random\n",
    "import numpy as np\n",
    "import boto3\n",
    "import io\n",
    "import pickle\n",
    "dummy_data = {\"inputs\": np.random.rand(2, 45, 2, 3, 224, 224).tolist()}\n",
    "s3 = boto3.client(\"s3\")\n",
    "bucket = \"smokynet-inference-images-processed\"\n",
    "my_array_data = io.BytesIO()\n",
    "pickle.dump(dummy_data, my_array_data)\n",
    "my_array_data.seek(0)\n",
    "s3.upload_fileobj(my_array_data, bucket, 'mydummydata.pkl')"
   ]
  },
  {
   "cell_type": "code",
   "execution_count": null,
   "id": "809dee90",
   "metadata": {},
   "outputs": [],
   "source": [
    "arr = np.random.rand(1, 1, 2, 3, 224, 224)\n",
    "arr.size * arr.itemsize"
   ]
  },
  {
   "cell_type": "code",
   "execution_count": 6,
   "id": "6f6d4d5d",
   "metadata": {},
   "outputs": [
    {
     "ename": "ModelError",
     "evalue": "An error occurred (ModelError) when calling the InvokeEndpoint operation: Received server error (500) from primary with message \"shape '[1, 1, 155, 279]' is invalid for input of size 961\nTraceback (most recent call last):\n  File \"/opt/conda/lib/python3.6/site-packages/sagemaker_inference/transformer.py\", line 126, in transform\n    result = self._transform_fn(self._model, input_data, content_type, accept)\n  File \"/opt/conda/lib/python3.6/site-packages/sagemaker_inference/transformer.py\", line 216, in _default_transform_fn\n    prediction = self._predict_fn(data, model)\n  File \"/opt/ml/model/code/inference.py\", line 91, in predict_fn\n    prediction = model(input_object)\n  File \"/opt/conda/lib/python3.6/site-packages/torch/nn/modules/module.py\", line 1102, in _call_impl\n    return forward_call(*input, **kwargs)\n  File \"/opt/ml/model/code/inference.py\", line 27, in forward\n    outputs, x = sub_model(x, bbox_labels=bbox_labels, tile_outputs=outputs)\n  File \"/opt/conda/lib/python3.6/site-packages/torch/nn/modules/module.py\", line 1102, in _call_impl\n    return forward_call(*input, **kwargs)\n  File \"/opt/ml/model/code/model_components.py\", line 873, in forward\n    tile_embeddings = tile_embeddings.view(batch_size * series_length, 1, self.embeddings_height, self.embeddings_width)\nRuntimeError: shape '[1, 1, 155, 279]' is invalid for input of size 961\n\". See https://us-west-2.console.aws.amazon.com/cloudwatch/home?region=us-west-2#logEventViewer:group=/aws/sagemaker/Endpoints/pytorch-inference-2022-11-18-20-20-03-519 in account 113998783017 for more information.",
     "output_type": "error",
     "traceback": [
      "\u001b[0;31m---------------------------------------------------------------------------\u001b[0m",
      "\u001b[0;31mModelError\u001b[0m                                Traceback (most recent call last)",
      "\u001b[0;32m/tmp/ipykernel_25625/61776567.py\u001b[0m in \u001b[0;36m<cell line: 1>\u001b[0;34m()\u001b[0m\n\u001b[0;32m----> 1\u001b[0;31m \u001b[0mres\u001b[0m \u001b[0;34m=\u001b[0m \u001b[0mpredictor\u001b[0m\u001b[0;34m.\u001b[0m\u001b[0mpredict\u001b[0m\u001b[0;34m(\u001b[0m\u001b[0mdummy_data\u001b[0m\u001b[0;34m)\u001b[0m\u001b[0;34m\u001b[0m\u001b[0;34m\u001b[0m\u001b[0m\n\u001b[0m",
      "\u001b[0;32m~/anaconda3/envs/pytorch_p38/lib/python3.8/site-packages/sagemaker/predictor.py\u001b[0m in \u001b[0;36mpredict\u001b[0;34m(self, data, initial_args, target_model, target_variant, inference_id)\u001b[0m\n\u001b[1;32m    159\u001b[0m             \u001b[0mdata\u001b[0m\u001b[0;34m,\u001b[0m \u001b[0minitial_args\u001b[0m\u001b[0;34m,\u001b[0m \u001b[0mtarget_model\u001b[0m\u001b[0;34m,\u001b[0m \u001b[0mtarget_variant\u001b[0m\u001b[0;34m,\u001b[0m \u001b[0minference_id\u001b[0m\u001b[0;34m\u001b[0m\u001b[0;34m\u001b[0m\u001b[0m\n\u001b[1;32m    160\u001b[0m         )\n\u001b[0;32m--> 161\u001b[0;31m         \u001b[0mresponse\u001b[0m \u001b[0;34m=\u001b[0m \u001b[0mself\u001b[0m\u001b[0;34m.\u001b[0m\u001b[0msagemaker_session\u001b[0m\u001b[0;34m.\u001b[0m\u001b[0msagemaker_runtime_client\u001b[0m\u001b[0;34m.\u001b[0m\u001b[0minvoke_endpoint\u001b[0m\u001b[0;34m(\u001b[0m\u001b[0;34m**\u001b[0m\u001b[0mrequest_args\u001b[0m\u001b[0;34m)\u001b[0m\u001b[0;34m\u001b[0m\u001b[0;34m\u001b[0m\u001b[0m\n\u001b[0m\u001b[1;32m    162\u001b[0m         \u001b[0;32mreturn\u001b[0m \u001b[0mself\u001b[0m\u001b[0;34m.\u001b[0m\u001b[0m_handle_response\u001b[0m\u001b[0;34m(\u001b[0m\u001b[0mresponse\u001b[0m\u001b[0;34m)\u001b[0m\u001b[0;34m\u001b[0m\u001b[0;34m\u001b[0m\u001b[0m\n\u001b[1;32m    163\u001b[0m \u001b[0;34m\u001b[0m\u001b[0m\n",
      "\u001b[0;32m~/anaconda3/envs/pytorch_p38/lib/python3.8/site-packages/botocore/client.py\u001b[0m in \u001b[0;36m_api_call\u001b[0;34m(self, *args, **kwargs)\u001b[0m\n\u001b[1;32m    393\u001b[0m                     \"%s() only accepts keyword arguments.\" % py_operation_name)\n\u001b[1;32m    394\u001b[0m             \u001b[0;31m# The \"self\" in this scope is referring to the BaseClient.\u001b[0m\u001b[0;34m\u001b[0m\u001b[0;34m\u001b[0m\u001b[0;34m\u001b[0m\u001b[0m\n\u001b[0;32m--> 395\u001b[0;31m             \u001b[0;32mreturn\u001b[0m \u001b[0mself\u001b[0m\u001b[0;34m.\u001b[0m\u001b[0m_make_api_call\u001b[0m\u001b[0;34m(\u001b[0m\u001b[0moperation_name\u001b[0m\u001b[0;34m,\u001b[0m \u001b[0mkwargs\u001b[0m\u001b[0;34m)\u001b[0m\u001b[0;34m\u001b[0m\u001b[0;34m\u001b[0m\u001b[0m\n\u001b[0m\u001b[1;32m    396\u001b[0m \u001b[0;34m\u001b[0m\u001b[0m\n\u001b[1;32m    397\u001b[0m         \u001b[0m_api_call\u001b[0m\u001b[0;34m.\u001b[0m\u001b[0m__name__\u001b[0m \u001b[0;34m=\u001b[0m \u001b[0mstr\u001b[0m\u001b[0;34m(\u001b[0m\u001b[0mpy_operation_name\u001b[0m\u001b[0;34m)\u001b[0m\u001b[0;34m\u001b[0m\u001b[0;34m\u001b[0m\u001b[0m\n",
      "\u001b[0;32m~/anaconda3/envs/pytorch_p38/lib/python3.8/site-packages/botocore/client.py\u001b[0m in \u001b[0;36m_make_api_call\u001b[0;34m(self, operation_name, api_params)\u001b[0m\n\u001b[1;32m    723\u001b[0m             \u001b[0merror_code\u001b[0m \u001b[0;34m=\u001b[0m \u001b[0mparsed_response\u001b[0m\u001b[0;34m.\u001b[0m\u001b[0mget\u001b[0m\u001b[0;34m(\u001b[0m\u001b[0;34m\"Error\"\u001b[0m\u001b[0;34m,\u001b[0m \u001b[0;34m{\u001b[0m\u001b[0;34m}\u001b[0m\u001b[0;34m)\u001b[0m\u001b[0;34m.\u001b[0m\u001b[0mget\u001b[0m\u001b[0;34m(\u001b[0m\u001b[0;34m\"Code\"\u001b[0m\u001b[0;34m)\u001b[0m\u001b[0;34m\u001b[0m\u001b[0;34m\u001b[0m\u001b[0m\n\u001b[1;32m    724\u001b[0m             \u001b[0merror_class\u001b[0m \u001b[0;34m=\u001b[0m \u001b[0mself\u001b[0m\u001b[0;34m.\u001b[0m\u001b[0mexceptions\u001b[0m\u001b[0;34m.\u001b[0m\u001b[0mfrom_code\u001b[0m\u001b[0;34m(\u001b[0m\u001b[0merror_code\u001b[0m\u001b[0;34m)\u001b[0m\u001b[0;34m\u001b[0m\u001b[0;34m\u001b[0m\u001b[0m\n\u001b[0;32m--> 725\u001b[0;31m             \u001b[0;32mraise\u001b[0m \u001b[0merror_class\u001b[0m\u001b[0;34m(\u001b[0m\u001b[0mparsed_response\u001b[0m\u001b[0;34m,\u001b[0m \u001b[0moperation_name\u001b[0m\u001b[0;34m)\u001b[0m\u001b[0;34m\u001b[0m\u001b[0;34m\u001b[0m\u001b[0m\n\u001b[0m\u001b[1;32m    726\u001b[0m         \u001b[0;32melse\u001b[0m\u001b[0;34m:\u001b[0m\u001b[0;34m\u001b[0m\u001b[0;34m\u001b[0m\u001b[0m\n\u001b[1;32m    727\u001b[0m             \u001b[0;32mreturn\u001b[0m \u001b[0mparsed_response\u001b[0m\u001b[0;34m\u001b[0m\u001b[0;34m\u001b[0m\u001b[0m\n",
      "\u001b[0;31mModelError\u001b[0m: An error occurred (ModelError) when calling the InvokeEndpoint operation: Received server error (500) from primary with message \"shape '[1, 1, 155, 279]' is invalid for input of size 961\nTraceback (most recent call last):\n  File \"/opt/conda/lib/python3.6/site-packages/sagemaker_inference/transformer.py\", line 126, in transform\n    result = self._transform_fn(self._model, input_data, content_type, accept)\n  File \"/opt/conda/lib/python3.6/site-packages/sagemaker_inference/transformer.py\", line 216, in _default_transform_fn\n    prediction = self._predict_fn(data, model)\n  File \"/opt/ml/model/code/inference.py\", line 91, in predict_fn\n    prediction = model(input_object)\n  File \"/opt/conda/lib/python3.6/site-packages/torch/nn/modules/module.py\", line 1102, in _call_impl\n    return forward_call(*input, **kwargs)\n  File \"/opt/ml/model/code/inference.py\", line 27, in forward\n    outputs, x = sub_model(x, bbox_labels=bbox_labels, tile_outputs=outputs)\n  File \"/opt/conda/lib/python3.6/site-packages/torch/nn/modules/module.py\", line 1102, in _call_impl\n    return forward_call(*input, **kwargs)\n  File \"/opt/ml/model/code/model_components.py\", line 873, in forward\n    tile_embeddings = tile_embeddings.view(batch_size * series_length, 1, self.embeddings_height, self.embeddings_width)\nRuntimeError: shape '[1, 1, 155, 279]' is invalid for input of size 961\n\". See https://us-west-2.console.aws.amazon.com/cloudwatch/home?region=us-west-2#logEventViewer:group=/aws/sagemaker/Endpoints/pytorch-inference-2022-11-18-20-20-03-519 in account 113998783017 for more information."
     ]
    }
   ],
   "source": [
    "\n",
    "\n",
    "res = predictor.predict('bucket_name' : 'smokynet-inference-images-processed','file_name' :'mydummydata.pkl')"
   ]
  },
  {
   "cell_type": "code",
   "execution_count": null,
   "id": "fe3a0332",
   "metadata": {},
   "outputs": [],
   "source": [
    "!pip install transformers"
   ]
  },
  {
   "cell_type": "markdown",
   "id": "c4eb87da",
   "metadata": {},
   "source": [
    "#### Delete endpoint"
   ]
  },
  {
   "cell_type": "code",
   "execution_count": null,
   "id": "5aae5524",
   "metadata": {},
   "outputs": [],
   "source": [
    "import os\n",
    "\n",
    "if not local_mode:\n",
    "    predictor.delete_endpoint()\n",
    "else:\n",
    "    os.system(\"docker container ls | grep 8080 | awk '{print $1}' | xargs docker container rm -f\")"
   ]
  }
 ],
 "metadata": {
  "kernelspec": {
   "display_name": "conda_pytorch_p38",
   "language": "python",
   "name": "conda_pytorch_p38"
  },
  "language_info": {
   "codemirror_mode": {
    "name": "ipython",
    "version": 3
   },
   "file_extension": ".py",
   "mimetype": "text/x-python",
   "name": "python",
   "nbconvert_exporter": "python",
   "pygments_lexer": "ipython3",
   "version": "3.8.12"
  }
 },
 "nbformat": 4,
 "nbformat_minor": 5
}
